Workbook

Sheet Index
B1: Index
B3: Index
B9: Click on any section name to proceed directly to that part of the assessment
B10: Domain | D10: Section | I10: Questions remaining
B11: Introduction | D11: 1. Introduction | I11: N/A
D12: 2. Usage | I12: N/A
D13: 3. Change notes | J13: N/A
I14: Questions remaining
B15: General | D15: 1. Profile | I15: N/A
D16: 2. Scope | I16: N/A
I17: Questions remaining
B18: Business | D18: 1. Business drivers | I18: =CONCATENATE(COUNTIFS(_Output!A:A,"B 1*",_Output!B:B,1,_Output!L:L,"<>NIST MAPPING",_Output!D:D, 0,_Output!E:E, ">1"),"/", COUNTIFS(_Output!A:A,"B 1*",_Output!B:B,1,_Output!L:L,"<>NIST MAPPING",_Output!E:E, ">1")) -> 5/5
D19: 2. Customers & Stakeholders | I19: =CONCATENATE(COUNTIFS(_Output!A:A,"B 2*",_Output!B:B,1,_Output!L:L,"<>NIST MAPPING",_Output!D:D, 0,_Output!E:E, ">1"),"/",COUNTIFS(_Output!A:A,"B 2*",_Output!B:B,1,_Output!L:L,"<>NIST MAPPING",_Output!E:E, ">1")) -> 6/6
D20: 3. Charter | I20: =CONCATENATE(COUNTIFS(_Output!A:A,"B 3*",_Output!B:B,1,_Output!L:L,"<>NIST MAPPING",_Output!D:D, 0,_Output!E:E, ">1"),"/", COUNTIFS(_Output!A:A,"B 3*",_Output!B:B,1,_Output!L:L,"<>NIST MAPPING",_Output!E:E, ">1")) -> 4/4
D21: 4. Governance | I21: =CONCATENATE(COUNTIFS(_Output!A:A,"B 4*",_Output!B:B,1,_Output!L:L,"<>NIST MAPPING",_Output!D:D, 0,_Output!E:E, ">1"),"/",COUNTIFS(_Output!A:A,"B 4*",_Output!B:B,1,_Output!L:L,"<>NIST MAPPING",_Output!E:E, ">1")) -> 9/9
D22: 5. Privacy & Policy | I22: =CONCATENATE(COUNTIFS(_Output!A:A,"B 5*",_Output!B:B,1,_Output!L:L,"<>NIST MAPPING",_Output!D:D, 0,_Output!E:E, ">1"),"/",COUNTIFS(_Output!A:A,"B 5*",_Output!B:B,1,_Output!L:L,"<>NIST MAPPING",_Output!E:E, ">1")) -> 10/10
I23: Questions remaining
B24: People | D24: 1. Employees | I24: =CONCATENATE(COUNTIFS(_Output!A:A,"P 1*",_Output!B:B,1,_Output!L:L,"<>NIST MAPPING",_Output!D:D, 0,_Output!E:E, ">1"),"/",COUNTIFS(_Output!A:A,"P 1*",_Output!B:B,1,_Output!L:L,"<>NIST MAPPING",_Output!E:E, ">1")) -> 9/9
D25: 2. Roles and Hierarchy | I25: =CONCATENATE(COUNTIFS(_Output!A:A,"P 2*",_Output!B:B,1,_Output!L:L,"<>NIST MAPPING",_Output!D:D, 0,_Output!E:E, ">1"),"/",COUNTIFS(_Output!A:A,"P 2*",_Output!B:B,1,_Output!L:L,"<>NIST MAPPING",_Output!E:E, ">1")) -> 8/8
D26: 3. People Management | I26: =CONCATENATE(COUNTIFS(_Output!A:A,"P 3*",_Output!B:B,1,_Output!L:L,"<>NIST MAPPING",_Output!D:D, 0,_Output!E:E, ">1"),"/",COUNTIFS(_Output!A:A,"P 3*",_Output!B:B,1,_Output!L:L,"<>NIST MAPPING",_Output!E:E, ">1")) -> 14/14
D27: 4. Knowledge Management | I27: =CONCATENATE(COUNTIFS(_Output!A:A,"P 4*",_Output!B:B,1,_Output!L:L,"<>NIST MAPPING",_Output!D:D, 0,_Output!E:E, ">1"),"/",COUNTIFS(_Output!A:A,"P 4*",_Output!B:B,1,_Output!L:L,"<>NIST MAPPING",_Output!E:E, ">1")) -> 8/8
D28: 5. Training & Education | I28: =CONCATENATE(COUNTIFS(_Output!A:A,"P 5*",_Output!B:B,1,_Output!L:L,"<>NIST MAPPING",_Output!D:D, 0,_Output!E:E, ">1"),"/",COUNTIFS(_Output!A:A,"P 5*",_Output!B:B,1,_Output!L:L,"<>NIST MAPPING",_Output!E:E, ">1")) -> 7/7
I29: Questions remaining
B30: Process | D30: 1. SOC Management | I30: =CONCATENATE(COUNTIFS(_Output!A:A,"M 1*",_Output!B:B,1,_Output!L:L,"<>NIST MAPPING",_Output!D:D, 0,_Output!E:E, ">1"),"/",COUNTIFS(_Output!A:A,"M 1*",_Output!B:B,1,_Output!L:L,"<>NIST MAPPING",_Output!E:E, ">1")) -> 7/7
D31: 2. Operations and Facilities | I31: =CONCATENATE(COUNTIFS(_Output!A:A,"M 2*",_Output!B:B,1,_Output!L:L,"<>NIST MAPPING",_Output!D:D, 0,_Output!E:E, ">1"),"/",COUNTIFS(_Output!A:A,"M 2*",_Output!B:B,1,_Output!L:L,"<>NIST MAPPING",_Output!E:E, ">1")) -> 20/20
D32: 3. Reporting & Communication | I32: =CONCATENATE(COUNTIFS(_Output!A:A,"M 3*",_Output!B:B,1,_Output!L:L,"<>NIST MAPPING",_Output!D:D, 0,_Output!E:E, ">1"),"/", COUNTIFS(_Output!A:A,"M 3*",_Output!B:B,1,_Output!L:L,"<>NIST MAPPING",_Output!E:E, ">1")) -> 17/17
D33: 4. Use Case Management | I33: =CONCATENATE(COUNTIFS(_Output!A:A,"M 4*",_Output!B:B,1,_Output!L:L,"<>NIST MAPPING",_Output!D:D, 0,_Output!E:E, ">1"),"/",COUNTIFS(_Output!A:A,"M 4*",_Output!B:B,1,_Output!L:L,"<>NIST MAPPING",_Output!E:E, ">1")) -> 20/20
D34: 5. Detection Engineering & Validation | I34: =CONCATENATE(COUNTIFS(_Output!A:A,"M 5*",_Output!B:B,1,_Output!L:L,"<>NIST MAPPING",_Output!D:D, 0, _Output!E:E, ">1"),"/",COUNTIFS(_Output!A:A,"M 5*",_Output!B:B,1,_Output!L:L,"<>NIST MAPPING", _Output!E:E, ">1")) -> 18/18
D35: 6. Automation Engineering | J35: =CONCATENATE(COUNTIFS(_Output!A:A,"M 6*",_Output!B:B,1,_Output!L:L,"<>NIST MAPPING",_Output!D:D, 0, _Output!E:E, ">1"),"/",COUNTIFS(_Output!A:A,"M 6*",_Output!B:B,1,_Output!L:L,"<>NIST MAPPING", _Output!E:E, ">1")) -> 10/10
D36: 7. Log Management | J36: =CONCATENATE(COUNTIFS(_Output!A:A,"M 7*",_Output!B:B,1,_Output!L:L,"<>NIST MAPPING",_Output!D:D, 0, _Output!E:E, ">1"),"/",COUNTIFS(_Output!A:A,"M 7*",_Output!B:B,1,_Output!L:L,"<>NIST MAPPING", _Output!E:E, ">1")) -> 8/8
I37: Questions remaining
B38: Technology | D38: 1. Log Monitoring | I38: =CONCATENATE(COUNTIFS(_Output!A:A,"T 1*",_Output!B:B,1,_Output!L:L,"<>NIST MAPPING",_Output!D:D, 0, _Output!E:E, ">1"),"/",COUNTIFS(_Output!A:A,"T 1*",_Output!B:B,1,_Output!L:L,"<>NIST MAPPING", _Output!E:E, ">1")) -> 60/60
D39: 2. Network Monitoring | I39: =CONCATENATE(COUNTIFS(_Output!A:A,"T 2*",_Output!B:B,1,_Output!L:L,"<>NIST MAPPING",_Output!D:D, 0, _Output!E:E, ">1"),"/",COUNTIFS(_Output!A:A,"T 2*",_Output!B:B,1,_Output!L:L,"<>NIST MAPPING",_Output!E:E, ">1")) -> 56/56
D40: 3. Endpoint Monitoring | I40: =CONCATENATE(COUNTIFS(_Output!A:A,"T 3*",_Output!B:B,1,_Output!L:L,"<>NIST MAPPING",_Output!D:D, 0, _Output!E:E, ">1"),"/",COUNTIFS(_Output!A:A,"T 3*",_Output!B:B,1,_Output!L:L,"<>NIST MAPPING", _Output!E:E, ">1")) -> 71/71
D41: 4. SecOps Automation | I41: =CONCATENATE(COUNTIFS(_Output!A:A,"T 4*",_Output!B:B,1,_Output!L:L,"<>NIST MAPPING",_Output!D:D, 0,_Output!E:E, ">1"),"/",COUNTIFS(_Output!A:A,"T 4*",_Output!B:B,1,_Output!L:L,"<>NIST MAPPING",_Output!E:E, ">1")) -> 46/46
I42: Questions remaining
B43: Services | D43: 1. Security Monitoring | I43: =CONCATENATE(COUNTIFS(_Output!A:A,"S 1*",_Output!B:B,1,_Output!L:L,"<>NIST MAPPING",_Output!D:D, 0, _Output!E:E, ">1"),"/",COUNTIFS(_Output!A:A,"S 1*",_Output!B:B,1,_Output!L:L,"<>NIST MAPPING",_Output!E:E, ">1")) -> 41/41
D44: 2. Security Incident Management | I44: =CONCATENATE(COUNTIFS(_Output!A:A,"S 2*",_Output!B:B,1,_Output!L:L,"<>NIST MAPPING",_Output!D:D, 0, _Output!E:E, ">1"),"/",COUNTIFS(_Output!A:A,"S 2*",_Output!B:B,1,_Output!L:L,"<>NIST MAPPING", _Output!E:E, ">1")) -> 52/52
D45: 3. Security Analysis and Forensics | I45: =CONCATENATE(COUNTIFS(_Output!A:A,"S 3*",_Output!B:B,1,_Output!L:L,"<>NIST MAPPING",_Output!D:D, 0, _Output!E:E, ">1"),"/",COUNTIFS(_Output!A:A,"S 3*",_Output!B:B,1,_Output!L:L,"<>NIST MAPPING", _Output!E:E, ">1")) -> 38/38
D46: 4. Threat Intelligence | I46: =CONCATENATE(COUNTIFS(_Output!A:A,"S 4*",_Output!B:B,1,_Output!L:L,"<>NIST MAPPING",_Output!D:D, 0, _Output!E:E, ">1"),"/",COUNTIFS(_Output!A:A,"S 4*",_Output!B:B,1,_Output!L:L,"<>NIST MAPPING", _Output!E:E, ">1")) -> 55/55
...

Sheet Introduction - INT
B1: Introduction
B3: 1. Introduction
B4: 2. Usage
B5: 3. Change notes
B19: General information
B20: Author | G20: Rob van Os
B21: Site | G21: https://www.soc-cmm.com/
B22: Contact | G22: info@soc-cmm.com
B23: Version | G23: 2.4.2, basic version
B24: Date | G24: April 16, 2026
B25: SOC-CMM training | G25: https://www.soc-cmm.com/services/training/
B26: SOC-CMM Support partners (for 3rd party assessment) | G26: https://www.soc-cmm.com/services/support/
B28: Background
B29: The SOC-CMM® model is a capability maturity model that can be used to perform a self-assessment of your Security Operations Center (SOC). The model is based on review conducted on literature regarding SOC setup and existing SOC models as well as literature on specific elements within a SOC. The literature analysis was then validated by questioning several Security Operations Centers in different sectors and on different maturity levels to determine which elements were actually in place. The output from the survey, combined with the initial analysis is the basis for this self-assessment. For more information regarding the scientific background and the literature used to create the SOC-CMM self-assessment tool, please refer to the thesis document as available through: https://www.soc-cmm.com/ If you have any questions or comments regarding the contents of this document, please use the above information to contact SOC-CMM®.
B38: Purpose and intended audience
B39: The purpose of the SOC-CMM is to gain insight into the strengths and weaknesses of the SOC. This enables the SOC management to make informed decisions about which elements of the SOC require additional attention and/or budget. By regularly assessing the SOC for maturity and capability, progress can be monitored. Besides the primary purpose of performing an assessment of the SOC, the assessment can also be used for extensive discussions about the SOC and can thus provide valuable insights. This tool is intended for use by SOC and security managers, experts within the SOC and SOC consultants.
B46: Navigation
B47: Navigation through this tool is done using the navigation bar at the top of each page. Each of the numbered sections can be clicked to proceed directly to that section. Furthermore, the icons can be used to navigate through sections within a domain and between domains. The icons are as follows:
C49: navigate to previous domain | H49: navigate to previous section within the domain
C51: navigate to index | H51: navigate to next section within the domain
C53: navigate to next domain | H53: navigate directly to results
B55: Assessment Model
B56: The assessment model consists of 5 domains and 27 aspects. All domains are evaluated for maturity (blue), only technology and services are evaluated for both maturity and capability (purple)
B78: Maturity Levels
B79: CMMI defines maturity as a means for an organization "to characterize its performance" for a specific entity (here: the SOC). The SOC-CMM calculates a maturity score using 6 maturity levels: - Level 0: non-existent - Level 1: initial - Level 2: managed - Level 3: defined - Level 4: quantitatively managed - Level 5: optimizing These maturity levels are measured across 5 domains: business, people, process, technology and services. The maturity levels as implemented in this tool are not staged with pre-requisites for each level. Instead, every element adds individually to the maturity score: a continuous maturity model.
B88: Capability Levels
B89: Capabilities are indicators of completeness. In essence, capabilities can support maturity. The SOC-CMM calculates a capability score using 4 capability levels, similar to CMMi: - Level 0: incomplete - Level 1: performed - Level 2: managed - Level 3: defined These capability levels have a strong technical focus and are measured across 2 domains: technology and services. Similar to maturity levels, progress to a higher capability level is continuous. There are no prerequisites for advancing to a higher level, thus the capability growth is continuous as well.
B97: Disclaimer
B98: The SOC-CMM is provided without warranty of any kind. The author of the document cannot assure its accuracy and is not liable for any cost as a result of decisions based on the output of this tool. The usage of this tool does not in any way entitle the user to support or consultancy. By using this tool, you agree to these conditions.
B101: License
B102: Copyright (C) 2025 - SOC-CMM® The SOC-CMM advanced version is part of the SOC-CMM®. The SOC-CMM® assessment tool is free software, released under the CC SA-BY license: https://creativecommons.org/licenses/by-sa/4.0/ You are free to: Share — copy and redistribute the material in any medium or format Adapt — remix, transform, and build upon the material for any purpose, even commercially. Under the following terms: Attribution — You must give appropriate credit, provide a link to the license, and indicate if changes were made. You may do so in any reasonable manner, but not in any way that suggests the licensor endorses you or your use. ShareAlike — If you remix, transform, or build upon the material, you must distribute your contributions under the same license as the original. No additional restrictions — You may not apply legal terms or technological measures that legally restrict others from doing anything the license permits. This license is acceptable for Free Cultural Works. The licensor cannot revoke these freedoms as long as you follow the license terms. This program is distributed in the hope that it will be useful, but WITHOUT ANY WARRANTY; without even the implied warranty of MERCHANTABILITY or FITNESS FOR A PARTICULAR PURPOSE.

Sheet Introduction - USG
B1: Introduction
B3: 1. Introduction
B4: 2. Usage
B5: 3. Change notes
B9: How to use the SOC-CMM assessment tool
B10: The SOC-CMM® assessement tool has an embedded workflow that guides the assessment. First, the profile sheet is filled in and the scope for assessment is selected. Then, the 5 domains of the SOC-CMM® model (i.e. Business, People, Process, Technology and Services) are each evaluated in separate sections of this tool. The evaluation is based on questions that can be answered using a drop-down that presents a 5-point scale. This scale relates to the maturity level as explained below under 'Scoring mechanism'. This tool should be used by assessing each sheet in order. When all domains are completed, the sheet 'Results' will provide you with the total scoring and detailed scoring for each domain. A sheet 'Next steps' is also included to provide pointers for follow-up. In the advanced version only, there is also a weighing mechanism in place. For each question, the importance of that element can be changed. The standard importance is 'normal', which means that the score is not modified. Changing to importance to 'low' will cause the element to have less impact on the score. Changing it to 'High' or 'Critical' will cause the element to have more impact on the score. Setting it to 'none' will ignore the element in scoring entirely, as explained under 'Weighing mechanism'. This feature should be used with care. Some additional remarks regarding the usage of the SOC-CMM® assessment tool: 1. Some elements are not used directly for scoring (this is also indicated), but are a guideline for answering other questions. These elements have a lighter colour. For example, question 3.1 (part of maturity score) can be answered by using the elements in 3.2 (not part of maturity score) as a guideline. 2. Elements with a green colour are calculated fields. These will be filled in automatically by filling in those parts of the assessment. 3. The services and Technology domains evaluate both maturity and capability. These capabilities do not have a 5-point scale and an importance, but use a 6-point scale instead. This is to reduce the amount of clicks and answers. The sixth element in the scale is 'not required'. Use this if you do not feel like you need that particular capability and to exclude it from scoring. 4. Every sheet has a part where you can fill in some comments or remarks. Discussing the questions in this self-assessments will likely uncover some improvements. This is added value for a self-assessment, so it is worthwhile to create notes. 5. The weighing mechanisms allows for manipulation of the maturity score. Therefore, it is important to strongly consider and possibly document why you wish to deviate from the standard. The goal of the SOC-CMM is to provide insight into strengths and weaknesses and to improve the SOC, not to obtain the highest score possible. 6. The NIST score is calculated automatically as explained below 7. Performing a full SOC-CMM® assessment can take a significant amount of time, depending on the level of detail you put into the assessment. Before you start, ensure that you have allocated sufficient time. A way to reduce effort is to have a single knowledgeable SOC employee perform a quick scan and subsequently focus on areas that are debatable. Also, reducing scope for an initial assessment is a way to reduce the assessment effort.
B31: Scoring mechanism
B32: Each question that is part of the maturity scoring can be answered by selecting one of 5 options. These options vary based on the type of question. For example, for questions regarding completeness, the following applies: - Incomplete, score: 0 - Partially complete, score: 1,25 - Averagely complete, score: 2,5 - Mostly complete, score: 3,75 - Fully complete, score: 5 As indicated, the score can be modified by using the weighing mechanism (use with care)
B39: Guidance
B40: For each of the maturity questions, guidance is available. When a value is selected from the dropdown box, guidance for that value is show under the guidance column. This guidance can be used to help determine the correct level. Note that this is truly meant as guidance on interpretation and scoring, not as mandatory and prescriptive.
B43: Weighing mechanism (advanced version only)
B44: The weighing mechanism in the tool works by applying a factor to the element score as follows: - Importance 'None', factor = 0 (not included in scoring) - Importance 'Low', factor = 0.5 (score divided by 2) - Importance 'Normal', factor = 1 (score not affected) - Importance 'High', factor = 2 (score doubled) - Importance 'Critical', factor = 4 (score quadrupled)
... B53: The SOC-CMM® assessment tool is built using standard Excel features without macros. The sheets are not locked or password protected. Therefore, adding columns and rows and applying other changes such as changing guidance or adding elements is possible. To show columns and rows, go to 'View' --> 'Show' and check 'Headings'. To show all the tabs underlying the SOC-CMM, go top 'File' --> 'Options' --> 'Advanced' --> 'Display options' and check 'Show sheet tabs'. Customizing calculations will require understanding of the calculations done in the '_Output' sheet. However, guidance for this type of customization is not provided, as it requires an understanding of the way the SOC-CMM® assessment tool sheets are connected.

Sheet Introduction - CHG
B1: Introduction
B3: 1. Introduction
B4: 2. Usage
B5: 3. Change notes
B9: Version 2.4.2 | D9: 16.4.2026
B11: General
C12: Updated scoped out visualization. Scope out elements now shown in red strike-through tekst
B14: Profile
C15: Scope
D16: Updated scoping element to make them clickable links
B18: Business
C19: Governance
D20: Updated guidance and description for external collaboration (4.11)
C21: Privacy & Policy
D22: Added 'interaction with public media' and 'SOC internet presence' to SOC policy to increase alignment with SIM3
B24: People
C25: Employees
D26: Added a question on retention strategy
B28: Process
C29: Operations & Facilities
D30: Question 2.2.6 added on emergency reachability to increase alignment with SIM3
D31: 2.4.1.6: Messaging system update to resilient messaging system to increase alignment with SIM3
D32: 2.4.1.7: added Resilient internet access to increase alignment with SIM3
D33: Fixed several incorrect references (non-functional)
B35: Services
C36: Security incident management
D37: Rearranged capabilities using the structure of NIST SP 800-61
D38: Renumbering applied for the new structure
D39: Escalation to press (2.17.25) and escalation to legal (2.17.26) functions added to increase alignment with SIM3
D40: (dedicated) information platform' renamed to '(dedicated/consolidated) information platform' to increase alignment with SIM3
B42: Results
C43: Results
D44: Calculation error for process domain average score corrected
B47: Version 2.4.1 | D47: 2.12.2025
B49: General
C50: Set all support questions to 'No' by default
C51: Left aligned some tekst for increased readability
C52: Corrected references in the Technology domain to named technologies from version 2.3
C53: Corrected 'Customers / Stakeholders' to 'Customers & Stakeholders' to align with the model
B55: Version 2.4 | D55: 1.11.2025
...

Sheet General - PRO
B1: Profile
B3: 1. Profile
B4: 2. Scope
B8: Please fill in the information below to create a short profile of the SOC and the assessment
B10: Assessment Details
B11: Date of assessment
B12: Name(s)
B16: Department(s)
B17: Intended purpose of the assessment and associated assessment objectives
B24: Assessment scope / SOC scope of operations
B28: Assessment type | K28: Click on the dropdown box for more information
B29: Assessment style | K29: Click on the dropdown box for more information
B31: Organisation & SOC Profile
B32: Business size (FTE)
B33: Sector
B34: Number of years of SOC operations
B35: SOC size (FTE's)
B36: SOC organisational model | K36: Click on the dropdown box for more information
B37: SOC region
B38: Geographic operation
B40: Target Maturity (optional)
B41: Target maturity level business domain | G41: 3 | K41: Indicate a score from 1 to 5. Decimals can be used
B42: Target maturity level people domain | G42: 3 | K42: Indicate a score from 1 to 5. Decimals can be used
B43: Target maturity level process domain | G43: 3 | K43: Indicate a score from 1 to 5. Decimals can be used
B44: Target maturity level technology domain | G44: 3 | K44: Indicate a score from 1 to 5. Decimals can be used
B45: Target maturity level services domain | G45: 3 | K45: Indicate a score from 1 to 5. Decimals can be used
B46: Target overall maturity level | G46: =IFERROR(SUM(G41:J45)/5, 0) -> 3
B48: Target Capability (optional)
B49: Target capability level technology domain | G49: 2 | K49: Indicate a score from 1 to 3. Decimals can be used
B50: Target capability level services domain | G50: 2 | K50: Indicate a score from 1 to 3. Decimals can be used
B51: Target overall capability level | G51: =IFERROR(SUM(G49:J50)/COUNT(G49:J50), 0) -> 2
B53: Notes or comments

Sheet General - SCP
B1: Profile
B3: 1. Profile
B4: 2. Scope
B8: Please select the services and technologies that should be included into the assessment. Excluding a service or technology here will exclude it from scoring. Note: changes to these values take some time to process
B10: SOC Tooling (Technology domain) | J10: Remarks
B11: 1. Log monitoring | J11: Log monitoring is used to gather logging, telemetry, and other relevant security data from company assets and centralise this information for alerting and analysis purposes
B12: 2. Network monitoring | J12: Network monitoring is to used detect network exploits, anomalous network activity, lateral movement, and to perform network forensics
B13: 3. Endpoint monitoring | J13: Endpoint monitoring used to prevent, detect, and respond to threats on end-points
B14: 4. SecOps automation | J14: SecOps atuomation is used to automate workflows and SOC actions, support incident response, and orchestrate between different security products
B16: SOC Services (services domain) | J16: Remarks
B17: 1. Security Monitoring | J17: Security monitoring aims at detecting security incidents and anomalies through centralised collection, processing and analysis of security events
B18: 2. Security Incident Management | J18: Security incident management aims at responding to security incidents in a timely, accurate and organized fashion to limit or negate incident impact
B19: 3. Forensic Analysis | J19: Forensic analysis supports security incident management by introducing forensic and malware analysis capabilities
B20: 4. Cyber Threat Intelligence | J20: Threat intelligence is the act of collecting and analysing information about potential threats and threat actors that can be used in security monitoring, security incident response, security analysis and threat hunting
B21: 5. Threat Hunting | J21: Threat hunting is a proactive monitoring activity used to uncovering threats in the infrastructure through searcing for TTPs, based on threat intelligence and the "assume breach" principle
B22: 6. Vulnerability Management | J22: Vulnerability management is the act of detecting vulnerabilities in assets by actively scanning assets for known vulnerabilities, analysing outcomes, and following up through remediation

Sheet Business - BSD
B1: Business
B3: 1. Business Drivers | G3: 5. Privacy & Policy
B4: 2. Customers & Stakeholders
B5: 3. Charter
B6: 4. Governance
A9: 1 | B9: Business Drivers | L9: Answer | N9: Guidance | O9: Remarks
B10: 1.1 | C10: Have you identified the main business drivers? | N10: =VLOOKUP(_Output!D4,_Guidance!B4:C9,2,FALSE) | O10: Example business drivers: cyber crime prevention, risk reduction, law / regulation, audit / compliance, business continuity
B11: 1.2 | C11: Have you documented the main business drivers? | N11: =VLOOKUP(_Output!D5,_Guidance!B10:C15,2,FALSE) | O11: Documentation of business drivers is important for demonstrable business alignment
B12: 1.3 | C12: Do you use business drivers in the decision making process? | N12: =VLOOKUP(_Output!D6,_Guidance!B16:C21,2,FALSE) | O12: e.g. to determine priorities or make decisions regarding the on-boarding of new services or operations
B13: 1.4 | C13: Do you regularly check if the current service catalogue is aligned with business drivers? | N13: =VLOOKUP(_Output!D7,_Guidance!B22:C27,2,FALSE) | O13: i.e. do you check for services or operations that outside the scope of business drivers?
B14: 1.5 | C14: Have the business drivers been validated with business stakeholders? | N14: =VLOOKUP(_Output!D8,_Guidance!B28:C33,2,FALSE) | O14: Business stakeholders can be C-level management
B16: Comments and/or Remarks
B17: 1.6 | C17: Specify rationale for chosen values or any additional comments | L17: 1.1
L18: 1.2
L19: 1.3
L20: 1.4
L21: 1.5

Sheet Business - CST
B1: Business
B3: 1. Business Drivers | G3: 5. Privacy & Policy
B4: 2. Customers & Stakeholders
B5: 3. Charter
B6: 4. Governance
A9: 2 | B9: Customers / Stakeholders | L9: Answer | N9: Guidance | O9: Remarks
B10: 2.1 | C10: Have you identified the SOC customers & stakeholders? | N10: =VLOOKUP(_Output!D12,_Guidance!B35:C40,2,FALSE) | O10: Types of customers and stakeholders, their requirements, expectations, etc.
B11: 2.2 | C11: Please specify your customers & stakeholders: | O11: Use this a guideline for answering 2.1 This is also potentially useful for insights and comparison with previous assessments
B12: 2.2.1 | C12: Legal | O12: Legal department, may be a stakeholder for privacy, or may request forensic investigation to the SOC
B13: 2.2.2 | C13: Audit | O13: The audit department can be supported by logging provided by the SOC
B14: 2.2.3 | C14: Engineering / R&D | O14: The engineering departments deal with Intellectual Property that may require additional access monitoring
B15: 2.2.4 | C15: IT | O15: IT departments can be supported by monitoring for anomalies in their infrastructure and systems
B16: 2.2.5 | C16: Business | O16: Business should be the most important customers & stakeholders, as all SOC activities ultimately support business processes
B17: 2.2.6 | C17: External customers & stakeholders | O17: External customers mostly apply to managed service providers. External stakeholders can by regulatory bodies
B18: 2.2.7 | C18: (Senior) Management | O18: Senior management may be a direct SOC customer & stakeholder, depending on organization hierarchy
B19: 2.2.8 | C19: Other customers & stakeholders: | O19: Specify any additional customers & stakeholders
B20: 2.3 | C20: Have you documented the main SOC customers & stakeholders? | N20: =VLOOKUP(_Output!D22,_Guidance!B41:C46,2,FALSE) | O20: Formal registration of customer & stakeholder contact details, function, agreements, etc.
B21: 2.4 | C21: Do you differentiate output towards these specific customers & stakeholders? | N21: =VLOOKUP(_Output!D23,_Guidance!B47:C52,2,FALSE) | O21: Differentiating output is helpful to match expectations of customers & stakeholders
B22: 2.5 | C22: Do you have service level agreements with these customers & stakeholders? | N22: =VLOOKUP(_Output!D24,_Guidance!B53:C58,2,FALSE) | O22: Service level agreements are used to provide standardized services operating within known boundaries
B23: 2.6 | C23: Do you regularly send updates to your customers & stakeholders? | N23: =VLOOKUP(_Output!D25,_Guidance!B59:C64,2,FALSE) | O23: For example: changes in service scope or delivery. Can also be reports, dashboards, etc.
B24: 2.7 | C24: Do you actively measure and manage customer & stakeholder satisfaction? | N24: =VLOOKUP(_Output!D26,_Guidance!B65:C70,2,FALSE) | O24: Understanding customer & stakeholder satisfaction will help to better align with business needs
B26: Comments and/or Remarks
B27: 2.8 | C27: Specify rationale for chosen values or any additional comments | L27: 2.1
L28: 2.2
L29: 2.3
L30: 2.4
L31: 2.5
L32: 2.6
L33: 2.7

Sheet Business - CHT
B1: Business
B3: 1. Business Drivers | G3: 5. Privacy & Policy
B4: 2. Customers & Stakeholders
B5: 3. Charter
B6: 4. Governance
A9: 3 | B9: Charter | L9: Answer | N9: Guidance | O9: Remarks
B10: 3.1 | C10: Does the SOC have a formal charter document in place? | N10: =VLOOKUP(_Output!D30,_Guidance!B72:C77,2,FALSE) | O10: See 3.2 for charter document elements
B11: 3.2 | C11: Please specify elements of the charter document:
B12: 3.2.1 | C12: Mission | O12: A SOC mission should be established to provide insight into the reason for existence of the SOC
B13: 3.2.2 | C13: Vision | O13: A vision should be created to determine long-term goals for the SOC
B14: 3.2.3 | C14: Strategy | O14: A strategy should be in place to show how to meet goals and targets set by mission and vision
B15: 3.2.4 | C15: Service Scope | O15: Service scope is documented to provide insight into SOC service delivery
B16: 3.2.5 | C16: Deliverables | O16: The output provided by the SOC, for example: reports, incidents, investigations, advisories, etc.
B17: 3.2.6 | C17: Responsibilities | O17: Responsibilities of the SOC
B18: 3.2.7 | C18: Accountability | O18: Accountability for the SOC for actions taken
B19: 3.2.8 | C19: Operational Hours | O19: Operational hours of the SOC
B20: 3.2.9 | C20: Stakeholders | O20: All relevant stakeholders for the SOC
B21: 3.2.10 | C21: Objectives / Goals | O21: Objectives and goals should be concrete and measurable so that they are fit for reporting purposes
B22: 3.2.11 | C22: Statement of success | O22: A statement of success is used to determine when the SOC is successful. Should be aligned with goals and objectives
C23: Completeness | L23: =VLOOKUP(SUM(_Output!D32:D42),_SUM_Completeness!A3:B14,2,FALSE) -> Incomplete | O23: Use this outcome as a guideline to determine the score for 3.1
B24: 3.3 | C24: Is the SOC charter document regularly updated? | N24: =VLOOKUP(_Output!D43,_Guidance!B78:C83,2,FALSE) | O24: Regularity should be matched to your own internal policy. At least yearly is recommended
B25: 3.4 | C25: Is the SOC charter document approved by the business / CISO? | N25: =VLOOKUP(_Output!D44,_Guidance!B84:C89,2,FALSE) | O25: Approval from the relevant stakeholders will aid in business support for SOC operations
B26: 3.5 | C26: Are all stakeholders familiar with the SOC charter document contents? | N26: =VLOOKUP(_Output!D45,_Guidance!B90:C95,2,FALSE) | O26: Making stakeholders aware of the contents helps in getting organizational support for security operations
B28: Comments and/or Remarks
B29: 3.6 | C29: Specify rationale for chosen values or any additional comments | L29: 3.1
L30: 3.2
L31: 3.3
L32: 3.4
L33: 3.5

Sheet Business - GOV
B1: Business
B3: 1. Business Drivers | G3: 5. Privacy & Policy
B4: 2. Customers & Stakeholders
B5: 3. Charter
B6: 4. Governance
A9: 4 | B9: Governance | L9: Answer | N9: Guidance | O9: Remarks
B10: 4.1 | C10: Does the SOC have a governance process in place? | N10: =VLOOKUP(_Output!D49,_Guidance!B97:C102,2,FALSE) | O10: A governance process is required to determine the way the SOC should be managed
B11: 4.2 | C11: Have all governance elements been identified? | N11: =VLOOKUP(_Output!D50,_Guidance!B103:C108,2,FALSE) | O11: Possible governance elements can be found in under 4.3
B12: 4.3 | C12: Please specify identified governance elements
B13: 4.3.1 | C13: Business Alignment | O13: Aligning SOC operations to business needs
B14: 4.3.2 | C14: Accountability | O14: Note that this can be part of the SOC charter document. This does not automatically make it part of the governance process
B15: 4.3.3 | C15: Sponsorship | O15: Can be part of stakeholder management
B16: 4.3.4 | C16: Mandate | O16: Mandate for the SOC should be established so that the SOC can take action in crisis situations
B17: 4.3.5 | C17: Relationships & Third Party Management | O17: Both management of internal and external relationships
B18: 4.3.6 | C18: Vendor Engagement | O18: For example: active involvement of vendors in the creation of a vision and strategy for the SOC
B19: 4.3.7 | C19: Service Commitment | O19: For example: service level agreements and IT controls
B20: 4.3.8 | C20: Project / Program Management | O20: Project management for individual projects within the SOC / program management for larger transitions
B21: 4.3.9 | C21: Continual Improvement | O21: Improvement of the SOC and of SOC management
B22: 4.3.10 | C22: Span of control / federation governance | O22: Especially important for SOC setups where multiple SOCs exist within the same company
B23: 4.3.11 | C23: Outsourced service management | O23: Especially important for hybrid SOC setups. When using outsourcing, SLAs and oversight should be in place
B24: 4.3.12 | C24: SOC KPIs & Metrics | O24: These are discussed in more detail in the Process section regarding reporting
... B26: 4.3.14 | C26: Customer Engagement / Satisfaction | O26: Are customers an integral part of your security operations? Is their satisfaction of SOC services every inquired about?
C27: Completeness | L27: =VLOOKUP(SUM(_Output!D52:D65),_SUM_Completeness!A17:B31,2,FALSE) -> Incomplete | O27: Use this outcome as a guideline to determine the score for 4.2
B28: 4.4 | C28: Is cost management in place? | N28: =VLOOKUP(_Output!D66,_Guidance!B109:C114,2,FALSE) | O28: Managing costs is required to justify budget allocation for the SOC and ensure continued service delivery in the future
B29: 4.5 | C29: Please specify cost management elements
B30: 4.5.1 | C30: People cost | O30: Costs associated with employees. Should be managed to prove FTE requirements to stakeholders
B31: 4.5.2 | C31: Process cost | O31: Cost associated with processes. Should be managed to ensure process elements can be delivered
B32: 4.5.3 | C32: Technology cost | O32: Cost associated with technology. Should be managed to prove budget requirements for new technology or replacement
B33: 4.5.4 | C33: Services cost | O33: Cost associated with service delivery. Especially important for managed service providers to ensure a healthy business model
B34: 4.5.5 | C34: Facility cost | O34: Cost associated with facilities used by the SOC
B35: 4.5.6 | C35: Budget forecasting | O35: Forecasting of required budget over time. Should be aligned with business needs; increased spending must be justified
B36: 4.5.7 | C36: Budget alignment | O36: Alignment of budget with business requirements and drivers to ensure balanced spending on the SOC
B37: 4.5.8 | C37: Return on investment | O37: Prove the return on investment to stakeholders to ensure continued budget allocation
C38: Completeness | L38: =VLOOKUP(SUM(_Output!D68:D75),_SUM_Completeness!A34:B42,2,FALSE) -> Incomplete | O38: Use this outcome as a guideline to determine the score for 4.4
B39: 4.6 | C39: Are all governance elements formally documented? | N39: =VLOOKUP(_Output!D76,_Guidance!B115:C120,2,FALSE) | O39: Formal documentation should be signed off and stored in a quality management system
B40: 4.7 | C40: Are SOC governance meetings regularly held? | N40: =VLOOKUP(_Output!D1078,_Guidance!B121:C126,2,FALSE) | O40: Meetings at different levels (operational, tactical, strategic) should be formalised in Terms of Reference (ToR) and driven by metrics
B41: 4.8 | C41: Is the governance process regularly reviewed? | N41: =VLOOKUP(_Output!D77,_Guidance!B127:C132,2,FALSE) | O41: Frequency should be matched to your own internal policy. At least yearly is recommended
B42: 4.9 | C42: Is the governance process aligned with all stakeholders? | N42: =VLOOKUP(_Output!D78,_Guidance!B133:C138,2,FALSE) | O42: Alignment will help the SOC obtain required mandate, budget and management support
B43: 4.10 | C43: Is the SOC regularly audited or subjected to (external) assessments? | N43: =VLOOKUP(_Output!D79,_Guidance!B139:C144,2,FALSE) | O43: Frequency should be matched to the SOC policy. At least yearly is recommended. 3rd party assessments have a higher objectivity
B44: 4.11 | C44: Is there an active cooperation with other SOCs (external)? | N44: =VLOOKUP(_Output!D985,_Guidance!B145:C150,2,FALSE) | O44: External collaboration and networking, exchaning best practices, threat intelligence, and response actions with other SOCs
...

Sheet Business - PRV
B1: Business
B3: 1. Business Drivers | G3: 5. Privacy & Policy
B4: 2. Customers & Stakeholders
B5: 3. Charter
B6: 4. Governance
A9: 5 | B9: Privacy & Policy | L9: Answer | N9: Guidance | O9: Remarks
B10: 5.1 | C10: Is there an information security policy in place that supports the SOC activities? | N10: =VLOOKUP(_Output!D987,_Guidance!B152:C157,2,FALSE) | O10: A clear security policy that supports SOC operations provides guidance and helps to enforce mandate for the SOC in the organisation
B11: 5.2 | C11: Has a SOC policy been created? | N11: =VLOOKUP(_Output!D1079,_Guidance!B158:C163,2,FALSE) | O11: A SOC policy is to outline the rules to which SOC personnel and SOC management needs to adhere
B12: 5.3 | C12: Please specify elements of the SOC policy
B13: 5.3.1 | C13: Code of conduct | O13: How to behave in the SOC, mandatory and optional meetings, SOC culture, repercussions for non-compliance, etc.
B14: 5.3.2 | C14: Rules of engagement & responsibilities | O14: What activities can and can not be performed as part of the job
B15: 5.3.3 | C15: Review frequency of documentation | O15: What documentation is subjected to review and how often that documentation needs to be reviewed
B16: 5.3.4 | C16: SOC assessment frequency and type | O16: How often the SOC is assessed and in what manner (self-assessment, audit, external assessment, etc.)
B17: 5.3.5 | C17: Knowledge exchange and maintenance | O17: The means (meetings and platforms) for knowledge exchange and rules for maintenance of knowledge bases
B18: 5.3.6 | C18: Exercise frequency | O18: Frequency and type (table top, cyber range, red team, etc.) of exercises in the SOC
B19: 5.3.7 | C19: Usage of TLP / Classification and information handling | O19: Information exchange protocols. Especially important for collaborations outside the organisation
B20: 5.3.8 | C20: Interaction with public media | O20: Guidelines on how to deal with public media inquiries
B21: 5.3.9 | C21: SOC internet presence | O21: Presence on the internet for the SOC, including contact for abuse or other security related questions, and social media usage
B22: 5.3.10 | C22: Working agreements | O22: Agreements on length of meetings, length of agile sprints, transparency of completed work, etc.
C23: Completeness | L23: =VLOOKUP(SUM(_Output!D1081:D1088) + SUM(_Output!D1468:D1469),_SUM_Completeness!A155:B165,2,FALSE) -> Incomplete | O23: Use this outcome as a guideline to determine the score for 5.2
B24: 5.4 | C24: Is the SOC consulted in the creation and updates of operational security policy? | N24: =VLOOKUP(_Output!D989,_Guidance!B164:C169,2,FALSE) | O24: Consulting the SOC in the creation of security policy will ensure that SOC activities are properly mentioned and enforceable
B25: 5.5 | C25: Is a reporting policy for security incidents in place? | N25: =VLOOKUP(_Output!D991,_Guidance!B170:C175,2,FALSE) | O25: A reporting policy for security incidents will aid the SOC in identifying incidents and threats in the organization
B26: 5.6 | C26: Is a privacy policy regarding security monitoring of employees in place? | N26: =VLOOKUP(_Output!D83,_Guidance!B176:C181,2,FALSE) | O26: A privacy policy should state that monitoring of employees is possible within acceptable limits
B27: 5.7 | C27: Does the SOC operate in compliance with all applicable privacy laws and regulations? | N27: =VLOOKUP(_Output!D84,_Guidance!B182:C187,2,FALSE) | O27: Local laws and regulations as well as company policy may apply and should all be considered
B28: 5.8 | C28: Does the SOC cooperate with legal departments regarding privacy matters? | N28: =VLOOKUP(_Output!D87,_Guidance!B188:C193,2,FALSE) | O28: Cooperation will ensure that the SOC is enabled to perform activities, rather than blocked
B29: 5.9 | C29: Are specific procedures in place for dealing with privacy related investigations? | N29: =VLOOKUP(_Output!D88,_Guidance!B194:C199,2,FALSE) | O29: Privacy related issues require careful examination, especially those potentially leading to court cases
B30: 5.10 | C30: Is the SOC aware of all information that it processes and is subject to privacy regulations? | N30: =VLOOKUP(_Output!D89,_Guidance!B200:C205,2,FALSE) | O30: Such information includes IP addresses, customer identifiers, user names, host names (for personally owned devices), etc.
B31: 5.11 | C31: Is a Privacy Impact Assessment (PIA) regularly conducted? | N31: =VLOOKUP(_Output!D90,_Guidance!B206:C211,2,FALSE) | O31: Can be used to determine the impact of monitoring on privacy, and can help uncover potential violations
B33: Comments and/or Remarks
B34: 5.10 | C34: Specify rationale for chosen values or any additional comments | L34: 5.1
L35: 5.2
L36: 5.3
L37: 5.4
L38: 5.5
L39: 5.6
L40: 5.7
L41: 5.8
L42: 5.9
L43: 5.10
L44: 5.11

Sheet People - EMP
B1: People
B3: 1. Employees | G3: 5. Training & Education
B4: 2. Roles and Hierarchy
B5: 3. People Management
B6: 4. Knowledge Management
A9: 1 | B9: Employees | L9: Answer | N9: Guidance | O9: Remarks
B10: 1.1 | C10: How many FTE’s are in your SOC? | L10: ='General - PRO'!G35 -> 0 | O10: Include both internal and external FTE's
B11: 1.2 | C11: Do you use external employees / contractors in your SOC? | O11: External employees can be hired experts to fill in vacant positions or perform project activities
B12: 1.2.1 | C12: If yes, specify the number of external FTE's | O12: =IFERROR(CONCATENATE("Current ratio: ", ROUND(L12/L10*100, 2), "%"),"Current ratio: 0%") -> Current ratio: 0%
B13: 1.3 | C13: Does the current size of the SOC meet FTE requirements? | N13: =VLOOKUP(_Output!D98,_Guidance!B215:C220,2,FALSE) | O13: i.e. is the SOC size sufficient to realize business goals?
B14: 1.4 | C14: Does the SOC meet requirements for internal to external employee FTE ratio? | N14: =VLOOKUP(_Output!D99,_Guidance!B221:C226,2,FALSE) | O14: Note: requirements do not need to be explicit. Set importance to 'None' if you have no external employees.
B15: 1.5 | C15: Does the SOC meet requirements for internal to external employee skillset? | N15: =VLOOKUP(_Output!D100,_Guidance!B227:C232,2,FALSE) | O15: i.e. Are there any crucial skills amongst external employees? Set importance to 'None' if you have no external employees
B16: 1.6 | C16: Are all positions filled? | N16: =VLOOKUP(_Output!D101,_Guidance!B233:C238,2,FALSE) | O16: Unfilled positions may be due to deficiencies in the recruitment process
B17: 1.7 | C17: Do you have a recruitment process in place? | N17: =VLOOKUP(_Output!D102,_Guidance!B239:C244,2,FALSE) | O17: A recruitment process is required to obtain new employees in a market where talent is scarce
B18: 1.8 | C18: Do you have a talent acquisition process in place? | N18: =VLOOKUP(_Output!D103,_Guidance!B245:C250,2,FALSE) | O18: Talent sourcing can be vital for SOC success
B19: 1.9 | C19: Do you have specific KSAOs established for SOC personnel? | N19: =VLOOKUP(_Output!D995,_Guidance!B251:C256,2,FALSE) | O19: Knowledge, Skills, Abilities and Other attributes (KSAOs) should be in place: technical, cognitive, social and character
B20: 1.10 | C20: Do you actively seek to create a psychologically safe environment for SOC personnel? | N20: =VLOOKUP(_Output!D996,_Guidance!B257:C262,2,FALSE) | O20: A psychologically safe environment is an environment where everyone is able to speak their mind and feel valued
B21: 1.11 | C21: Do you have a defined retention strategy? | O21: A retention strategy is used to ensure that talent and key personnel is not lost
B24: Comments and/or Remarks
B25: 1.12 | C25: Specify rationale for chosen values or any additional comments | L25: 1.1
L26: 1.2
L27: 1.3
L28: 1.4
L29: 1.5
L30: 1.6
L31: 1.7
L32: 1.8
L33: 1.9
L34: 1.10
B35: References | L35: 1.11
B36: CISRT social maturity handbook

Sheet People - R&H
B1: People
B3: 1. Employees | G3: 5. Training & Education
B4: 2. Roles and Hierarchy
B5: 3. People Management
B6: 4. Knowledge Management
A9: 2 | B9: Roles and Hierarchy | L9: Answer | N9: Guidance | O9: Remarks
B10: 2.1 | C10: Do you formally differentiate roles within the SOC? | N10: =VLOOKUP(_Output!D107,_Guidance!B264:C269,2,FALSE) | O10: Use the roles in 2.2 to determine if you have all roles required in the SOC
B11: 2.2 | C11: Which of the following roles are present in your SOC?
B12: 2.2.1 | C12: Security Analyst | O12: Primarily responsible for triage and analysis of security alerts
B13: 2.2.2 | C13: Security / Systems Engineer | O13: Primarily responsible for technical / functional maintenance of security systems
B14: 2.2.3 | C14: Forensic Analyst | O14: Primarily responsible for in-depth analysis and security projects
B15: 2.2.4 | C15: Security Architect | O15: Primarily responsible for technical architecture for security systems used within the SOC
B16: 2.2.5 | C16: Threat Intelligence Analyst | O16: Primarily responsible for analysis of threat intelligence
B17: 2.2.6 | C17: Data Scientist | O17: Primarily responsible for big data security analytics
B18: 2.2.7 | C18: SOC Manager | O18: Primarily responsible for managing SOC services
B19: 2.2.8 | C19: Team Leader | O19: Primarily responsible for leading a team of other, for example, analysts and engineers
B20: 2.2.9 | C20: Incident Handler | O20: Primarily responsible for executing security incident management workflows
B21: 2.2.10 | C21: Incident Manager | O21: Primarily responsible for ensuring correct and timely management and escalation of security incidents
B22: 2.2.11 | C22: Penetration Tester | O22: Primarily responsible for testing applications and systems for security weaknesses
B23: 2.2.12 | C23: Detection engineer | O23: Primarily responsible for creating and updating detection analytics
... B25: 2.2.14 | C25: Others, specify: | O25: Specify any additional roles
B26: 2.3 | C26: Do you differentiate tiers within these roles? | N26: =VLOOKUP(_Output!D123,_Guidance!B270:C275,2,FALSE) | O26: If you have no tiers, and you feel this is not a restriction, select importance 'None'
B27: 2.4 | C27: Are all roles sufficiently staffed? | N27: =VLOOKUP(_Output!D125,_Guidance!B276:C281,2,FALSE) | O27: Consider the staffing levels (desired FTE count) as well as knowledge and experience for all roles
B28: 2.5 | C28: Is there a role-based hierarchy in your SOC? | N28: =VLOOKUP(_Output!D127,_Guidance!B282:C287,2,FALSE) | O28: If you have no hierarchy, and you feel this is not a restriction, select importance 'None'
B29: 2.6 | C29: Have you formally documented all SOC roles? | N29: =VLOOKUP(_Output!D128,_Guidance!B288:C293,2,FALSE) | O29: Possible documentation elements can be found in under 2.7
B30: 2.7 | C30: Please specify elements in the role documentation:
B31: 2.7.1 | C31: Role description | O31: A formal description of the role
B32: 2.7.2 | C32: Role tasks | O32: A description of tasks that are part of the role
B33: 2.7.3 | C33: Role responsibilities | O33: The responsibilities of the role
B34: 2.7.4 | C34: Role expectations | O34: This is an extension of responsibilities. Example expectation: take a pro-active leading role in case of security incidents
B35: 2.7.5 | C35: Required technical skills | O35: e.g. experience with specific technologies or products
B36: 2.7.6 | C36: Required soft skills | O36: e.g. communication skills, presentation skills
B37: 2.7.7 | C37: Required educational level | O37: e.g. university college, university
B38: 2.7.8 | C38: Required or preferred certifications | O38: e.g. technical security certifications or security management certifications
C39: Completeness | L39: =VLOOKUP(SUM(_Output!D132:D139),_SUM_Completeness!A58:B66,2,FALSE) -> Incomplete | O39: Use this outcome as a guideline to determine the score for 2.6
B40: 2.8 | C40: Are responsibilities for each role understood? | N40: =VLOOKUP(_Output!D140,_Guidance!B294:C299,2,FALSE) | O40: Responsibilities for each role should be clearly understood by all SOC personnel
B41: 2.9 | C41: Have you documented career progression requirements for each of these roles? | N41: =VLOOKUP(_Output!D143,_Guidance!B300:C305,2,FALSE) | O41: Career progression for roles can be documented through training, certification, experience and soft skills requirements
B42: 2.10 | C42: Do you regularly revise or update the role descriptions? | N42: =VLOOKUP(_Output!D144,_Guidance!B306:C311,2,FALSE) | O42: To revise is to review and verify whether to documentation is still correct or requires an update
B44: Comments and/or Remarks
B45: 2.11 | C45: Specify rationale for chosen values or any additional comments | L45: 2.1
...

Sheet People - PEM
B1: People
B3: 1. Employees | G3: 5. Training & Education
B4: 2. Roles and Hierarchy
B5: 3. People Management
B6: 4. Knowledge Management
A9: 3 | B9: People Management | L9: Answer | N9: Guidance | O9: Remarks
B10: 3.1 | C10: Do you have a job rotation plan in place? | N10: =VLOOKUP(_Output!D148,_Guidance!B314:C319,2,FALSE) | O10: Job rotation can be used to train employees in a variety of tasks and avoid too much routine
B11: 3.2 | C11: Do you have a career progression process in place? | N11: =VLOOKUP(_Output!D149,_Guidance!B320:C325,2,FALSE) | O11: Career development, promotion, etc.
B12: 3.3 | C12: Do you have a talent management process in place? | N12: =VLOOKUP(_Output!D150,_Guidance!B326:C331,2,FALSE) | O12: Talent should be adequately managed to retain such staff and fully develop their potential.
B13: 3.4 | C13: Do you have team diversity goals? | N13: =VLOOKUP(_Output!D151,_Guidance!B332:C337,2,FALSE) | O13: e.g. background diversity, ethnic diversity, gender diversity, etc.
B14: 3.5 | C14: Have you established team goals? | N14: =VLOOKUP(_Output!D997,_Guidance!B338:C343,2,FALSE) | O14: Team goals help to bring focus to the team and monitor progress
B15: 3.6 | C15: Do you document and track individual team member goals? | N15: =VLOOKUP(_Output!D998,_Guidance!B344:C349,2,FALSE) | O15: Individual team member goals should be set to help grow the employee to full potential
B16: 3.7 | C16: Do you periodically evaluate SOC employees? | N16: =VLOOKUP(_Output!D152,_Guidance!B350:C355,2,FALSE) | O16: Can also be included in the regular organization evaluation process
B17: 3.8 | C17: Do you have a 'new hire' process in place? | N17: =VLOOKUP(_Output!D153,_Guidance!B356:C361,2,FALSE) | O17: i.e. a defined process to quickly let new employees find their place and perform well in the SOC
B18: 3.9 | C18: Are all SOC employees subjected to screening? | N18: =VLOOKUP(_Output!D154,_Guidance!B362:C367,2,FALSE) | O18: Personnel screening is performed to avoid infiltration or misbehaviour by SOC employees
B19: 3.10 | C19: Do you measure employee satisfaction for improving the SOC? | N19: =VLOOKUP(_Output!D155,_Guidance!B368:C373,2,FALSE) | O19: Employee satisfaction should be taken seriously as lack of satisfaction may lead to key personnel leaving
B20: 3.11 | C20: Are there regular 1-on-1 meetings between the SOC manager and the employees? | N20: =VLOOKUP(_Output!D156,_Guidance!B374:C379,2,FALSE) | O20: Such informal 1-on-1 conversations are used to coach employees and help the SOC manager gain insight in personal challenges
B21: 3.12 | C21: Do you perform regular teambuilding exercises? | N21: =VLOOKUP(_Output!D157,_Guidance!B380:C385,2,FALSE) | O21: Teambuilding exercises are used to promote collaboration between individuals in the team and to raise team spirit
B22: 3.13 | C22: Do you perform regular teambuilding exercises with other teams relevant to the SOC? | N22: =VLOOKUP(_Output!D999,_Guidance!B386:C391,2,FALSE) | O22: In multi-team systems (MTS), the SOC collaborates with other teams. Use cross-team teambuilding to maximize performance
B23: 3.14 | C23: Do you periodically evaluate team performance? | N23: =VLOOKUP(_Output!D1000,_Guidance!B392:C397,2,FALSE) | O23: Besides individual performance, team performance and dynamics are also important to measure and improve on
B25: Comments and/or Remarks
B26: 3.15 | C26: Specify rationale for chosen values or any additional comments | L26: 3.1
L27: 3.2
L28: 3.3
L29: 3.4
L30: 3.5
L31: 3.6
L32: 3.7
L33: 3.8
L34: 3.9
L35: 3.10
L36: 3.11
L37: 3.12
L38: 3.13
L39: 3.14

Sheet People - KNM
B1: People
B3: 1. Employees | G3: 5. Training & Education
B4: 2. Roles and Hierarchy
B5: 3. People Management
B6: 4. Knowledge Management
A9: 4 | B9: Knowledge Management | L9: Answer | N9: Guidance | O9: Remarks
B10: 4.1 | C10: Do you have a formal knowledge management process in place? | N10: =VLOOKUP(_Output!D161,_Guidance!B400:C405,2,FALSE) | O10: Formal knowledge management helps to optimize knowledge creation and distribution
B11: 4.2 | C11: Do you have a skill matrix in place? | N11: =VLOOKUP(_Output!D1092,_Guidance!B406:C411,2,FALSE) | O11: A matrix may consist of: SOC skills, SOC employees and skill levels (novice, intermediate, expert)
B12: 4.3 | C12: Please specify elements of the skill matrix:
B13: 4.3.1 | C13: All SOC employees | O13: The skill matrix should cover all SOC employees, both internal and external
B14: 4.3.2 | C14: Hard skills | O14: e.g. ability to effectively use analysis tools
B15: 4.3.3 | C15: Soft skills | O15: e.g. communication skills
B16: 4.3.4 | C16: Skill levels (novice, intermediate, expert) | O16: Determining and documenting skill levels helps to identify areas where limited expertise is available
C17: Completeness | L17: =VLOOKUP(SUM(_Output!D1093:D1096),_SUM_Completeness!A197:B201,2,FALSE) -> Incomplete | O17: Use this outcome as a guideline to determine the score for 4.2
B18: 4.4 | C18: Is the skill matrix actively used for team and personal improvement? | N18: =VLOOKUP(_Output!D1097,_Guidance!B412:C417,2,FALSE) | O18: Personal improvement is essential, team improvement requires insight in team dynamics and skill distribution
B19: 4.5 | C19: Do you have a knowledge matrix in place? | N19: =VLOOKUP(_Output!D1098,_Guidance!B418:C423,2,FALSE)
B20: 4.6 | C20: Please specify elements of the knowledge matrix:
B21: 4.6.1 | C21: All SOC employees | O21: The knowledge matrix should cover all SOC employees, both internal and external
B22: 4.6.2 | C22: All relevant knowledge areas | O22: Knowledge for service delivery: technical (i.e. support), functional (i.e. configuration) and foundational (e.g. networking, encryption)
B23: 4.6.3 | C23: Knowledge levels (novice, intermediate, expert) | O23: Determining and documenting knowledge levels helps to identify areas where limited expertise is available
C24: Completeness | L24: =VLOOKUP(SUM(_Output!D1099:D1101),_SUM_Completeness!A204:B207,2,FALSE) -> Incomplete | O24: Use this outcome as a guideline to determine the score for 4.5
B25: 4.7 | C25: Is the knowledge matrix actively used to determine training and education needs? | N25: =VLOOKUP(_Output!D1102,_Guidance!B424:C429,2,FALSE) | O25: The matrix should be used as a means to identify and resolve knowledge gaps
B26: 4.8 | C26: Have you documented SOC team member abilities? | N26: =VLOOKUP(_Output!D1001,_Guidance!B430:C435,2,FALSE) | O26: Besides knowledge and skills, team member abilities are also important to document
B27: 4.9 | C27: Do you regularly assess and revise the knowledge management process? | N27: =VLOOKUP(_Output!D175,_Guidance!B436:C441,2,FALSE) | O27: This refers to the knowledge management process as a whole
B28: 4.10 | C28: Is there effective tooling in place to support knowledge documentation and distribution? | N28: =VLOOKUP(_Output!D176,_Guidance!B442:C447,2,FALSE) | O28: Such tooling can help to avoid investigation similar issues multiple times by integrating into the security monitoring process
B30: Comments and/or Remarks
B31: 4.11 | C31: Specify rationale for chosen values or any additional comments | L31: 4.1
L32: 4.2
L33: 4.3
L34: 4.4
L35: 4.5
L36: 4.6
L37: 4.7
L38: 4.8
L39: 4.9
L40: 4.10

Sheet People - T&E
B1: People
B3: 1. Employees | G3: 5. Training & Education
B4: 2. Roles and Hierarchy
B5: 3. People Management
B6: 4. Knowledge Management
A9: 5 | B9: Training and Education | L9: Answer | N9: Guidance | O9: Remarks
B10: 5.1 | C10: Do you have a training program in place? | N10: =VLOOKUP(_Output!D180,_Guidance!B450:C455,2,FALSE) | O10: A training program is used to ensure a minimal level of knowledge for employees
B11: 5.2 | C11: Please specify elements of the training program:
B12: 5.2.1 | C12: Training on the Job | O12: Training on the job can be done internally by senior employees or using external consultants
B13: 5.2.2 | C13: Product-specific training | O13: Product-specific training may be required for new technologies or complex solutions
B14: 5.2.3 | C14: Internal company training | O14: e.g. training on internal policies
B15: 5.2.4 | C15: Role-based specific training | O15: For example: security analysis training for the security analyst role
B16: 5.2.5 | C16: Soft-skill training | O16: To complement hard skills, soft skills should be trained as well
B17: 5.2.6 | C17: Formal education | O17: Formal education may be university or university college degrees
C18: Completeness | L18: =VLOOKUP(SUM(_Output!D182:D187),_SUM_Completeness!A69:B75,2,FALSE) -> Incomplete | O18: Use this outcome as a guideline to determine the score for 5.1
B19: 5.3 | C19: Do you have a certification program in place? | N19: =VLOOKUP(_Output!D188,_Guidance!B456:C461,2,FALSE) | O19: A certification program is used to provide a demonstrable minimum level of knowledge and skills
B20: 5.4 | C20: Please specify elements of the certification program:
B21: 5.4.1 | C21: Internal certification track | O21: Internal certifications may be in place to demonstrate knowledge of company processes and policies
B22: 5.4.2 | C22: External certification track | O22: Certification track with external certification organizations (e.g. ISACA, (ISC)2, SANS
B23: 5.4.3 | C23: Re-certification track (continuous education) | O23: Permanent education (PE) may be part of the certification itself
C24: Completeness | L24: =VLOOKUP(SUM(_Output!D190:D192),_SUM_Completeness!A78:B81,2,FALSE) -> Incomplete | O24: Use this outcome as a guideline to determine the score for 5.3
B25: 5.5 | C25: Is the training and certification program connected to evaluation and career progression? | N25: =VLOOKUP(_Output!D193,_Guidance!B462:C467,2,FALSE) | O25: e.g. certain training and certifications are required to grow from a junior level function to a more senior level function
B26: 5.6 | C26: Is there a reserved budget for education and training? | N26: =VLOOKUP(_Output!D194,_Guidance!B468:C473,2,FALSE) | O26: i.e. a fixed percentage of the total SOC budget that is allocated for education and cannot be used for other purposes
B27: 5.7 | C27: Is there a reserved amount of time for education and training? | N27: =VLOOKUP(_Output!D195,_Guidance!B474:C479,2,FALSE) | O27: This is an extension of education budget
B28: 5.8 | C28: Do you have regular workshops for knowledge development? | N28: =VLOOKUP(_Output!D196,_Guidance!B480:C485,2,FALSE) | O28: Workshops are an informal way of distributing knowledge
